Workbook
Name dFiltr: Dashboard!$M$4
Name lstDzialy: Parametry!$C$31:$C$35
Name lstFiltr: Parametry!$E$31:$E$35
Name lstPlacowki: Parametry!$A$31:$A$34
Name pDataRaportu: Parametry!$B$5
Name pNarzut: Parametry!$B$16
Name pPlacaMin: Parametry!$B$6

Sheet O projekcie
B1: Controlling personalny – sieć placówek medycznych
B2: Projekt portfolio: raportowanie danych HR w MS Excel (dane w pełni fikcyjne)
B4: Cel projektu
B5: Problem | C5: Dział HR otrzymuje surowy eksport kadrowo-płacowy z systemu HR (np. enova365) dla 4 placówek. Przed raportowaniem trzeba zweryfikować dane, policzyć koszty pracy, ocenić wynagrodzenia względem siatki płac i przygotować budżet na kolejny rok.
B6: Rozwiązanie | C6: Zintegrowany skoroszyt, w którym jeden eksport zasila wszystkie raporty. Zmiana danych lub założeń (np. płacy minimalnej, składek, podwyżek) automatycznie aktualizuje cały model.
B8: Struktura skoroszytu
B9: Dashboard | C9: Kafelki KPI (zatrudnienie, FTE, koszt pracy, średnie wynagrodzenie, rotacja, luka płacowa, jakość danych) i 4 wykresy. Filtr placówki z listy rozwijanej.
B10: Parametry | C10: Wszystkie założenia w jednym miejscu: data raportu, płaca minimalna 2026, składki pracodawcy (ZUS, FP, FGŚP, PPK), siatka płac G1–G6 i podwyżki na 2027.
B11: Dane_Kadrowe | C11: Tabela tblKadry (184 rekordy) – dane źródłowe + kolumny wyliczane (stawka na pełny etat, koszt pracodawcy, staż, compa-ratio, uwagi QC). Dane spseudonimizowane (tylko ID).
B12: Kontrola_Jakości | C12: 10 reguł walidacji, m.in. duplikaty, braki, płaca poniżej minimalnej, nieprawidłowy etat, niespójny status oraz zgodność z Kodeksem pracy (art. 25 i 25¹ KP). Automatyczna lista rekordów do poprawy.
B13: Koszty_Pracy | C13: Koszt pracodawcy wg placówek i działów, struktura składek, uzgodnienia kontrolne (sumy kontrolne = 0).
B14: Przegląd_Wynagrodzeń | C14: Pozycja w widełkach, compa-ratio, koszt wyrównania do minimum widełek, luka płacowa K/M z progiem 5% (dyrektywa UE 2023/970 o jawności wynagrodzeń), lista osób do przeglądu.
B15: Budżet_2027 | C15: Plan kosztów pracy: efekt podwyżek wg grup, nowe etaty (FTE × miesiące), porównanie r/r i most kosztów 2026 → 2027.
B17: Użyte techniki Excel
B18: Formuły | C18: XLOOKUP, SUMIFS / COUNTIFS / AVERAGEIFS, SUMPRODUCT, FILTER, SORT, CHOOSECOLS, TEXTJOIN, YEARFRAC, EOMONTH, MEDIAN
B19: Struktura | C19: Tabele z odwołaniami strukturalnymi, nazwy zakresów (pDataRaportu, pPlacaMin, pNarzut), sprawdzanie poprawności danych (lista rozwijana), formuły dynamiczne, sumy kontrolne
B20: Wizualizacja | C20: Formatowanie warunkowe (flagi błędów, skale kolorów, paski danych), wykresy reagujące na filtr, czytelny układ kafelków KPI
B22: Jak czytać kolory
B23: Niebieski na żółtym | C23: Dane wejściowe / założenia – można je zmieniać
B24: Czarny | C24: Formuły i obliczenia
B25: Zielony | C25: Powiązania z innymi arkuszami
B27: Uproszczenia | C27: Pominięto limit 30-krotności dla składek emerytalno-rentowych i zwolnienia z FP/FGŚP (wiek 55/60+). Stopa wypadkowa przyjęta umownie. Dane zawierają celowo wprowadzone błędy, które wychwytuje zakładka Kontrola_Jakości.

Sheet Arkusz2

Sheet Arkusz3

Sheet Arkusz4

Sheet Dashboard
B1: Dashboard HR – sieć placówek medycznych
B2: ="Dane na dzień "&YEAR(pDataRaportu)&"-"&TEXT(MONTH(pDataRaportu),"00")&"-"&TEXT(DAY(pDataRaportu),"00")&" | dane fikcyjne, przygotowane na potrzeby portfolio" -> Dane na dzień 2026-09-30 | dane fikcyjne, przygotowane na potrzeby portfolio
B4: Placówka: | C4: Ustroń | F4: ◄ wybierz z listy | L4: kryterium: | M4: =IF(C4="Wszystkie","*",C4) -> Ustroń
B6: Zatrudnienie (osoby) | D6: Koszt pracodawcy / mies. | F6: Śr. wynagrodzenie (etat) | H6: Rotacja YTD | J6: Luka płacowa K/M (nieskoryg.) | L6: Jakość danych
B7: =C52 -> 26 | D7: =SUMIFS(tblKadry[Koszt_pracodawcy_mies],tblKadry[Placówka],dFiltr,tblKadry[Aktywny_na_dzień],1) -> 307505.48 | F7: =IFERROR(AVERAGEIFS(tblKadry[Stawka_pełny_etat],tblKadry[Placówka],dFiltr,tblKadry[Aktywny_na_dzień],1),0) -> 9900.3846 | H7: =C55 -> 0.081632653 | J7: =IFERROR(1-AVERAGEIFS(tblKadry[Stawka_pełny_etat],tblKadry[Płeć],"K",tblKadry[Placówka],dFiltr,tblKadry[Aktywny_na_dzień],1)/AVERAGEIFS(tblKadry[Stawka_pełny_etat],tblKadry[Płeć],"M",tblKadry[Placówka],dFiltr,tblKadry[Aktywny_na_dzień],1),0) -> 0.3381629 | L7: =Kontrola_Jakości!C18 -> 0.92934783
B8: ="FTE: "&FIXED(SUMIFS(tblKadry[Etat],tblKadry[Placówka],dFiltr,tblKadry[Aktywny_na_dzień],1),1) -> FTE: 24,8 | D8: ="rocznie: "&FIXED(D7*12/1000000,2)&" mln zł" -> rocznie: 3,69 mln zł | F8: {="mediana: "&FIXED(IFERROR(MEDIAN(_xlfn._xlws.FILTER(tblKadry[Stawka_pełny_etat],(((tblKadry[Placówka]=$C$4)+($C$4="Wszystkie"))>0)*(tblKadry[Aktywny_na_dzień]=1)*(tblKadry[Stawka_pełny_etat]<>""))),0),0)&" zł"} -> mediana: 8 535 zł | H8: ="odejścia: "&C53&" | przyjęcia: "&C54 -> odejścia: 2 | przyjęcia: 5 | J8: =COUNTIFS(tblKadry[Pozycja_w_widełkach],"Poniżej",tblKadry[Placówka],dFiltr,tblKadry[Aktywny_na_dzień],1)&" os. poniżej widełek" -> 2 os. poniżej widełek | L8: =Kontrola_Jakości!C16&" rekordów do weryfikacji" -> 13 rekordów do weryfikacji
B40: Obliczenia pomocnicze (źródło wykresów i kafelków) – reagują na filtr placówki
B41: Dział | C41: FTE | D41: Koszt pracodawcy (mies.) | E41: Śr. stawka K | F41: Śr. stawka M | H41: Typ umowy | I41: Osoby | K41: Miesiąc | L41: Przyjęcia | M41: Odejścia
B42: =Parametry!C31 -> Kardiologia | C42: =SUMIFS(tblKadry[Etat],tblKadry[Dział],B42,tblKadry[Placówka],dFiltr,tblKadry[Aktywny_na_dzień],1) -> 9.5 | D42: =SUMIFS(tblKadry[Koszt_pracodawcy_mies],tblKadry[Dział],B42,tblKadry[Placówka],dFiltr,tblKadry[Aktywny_na_dzień],1) -> 152853.14 | E42: =IFERROR(AVERAGEIFS(tblKadry[Stawka_pełny_etat],tblKadry[Dział],B42,tblKadry[Płeć],"K",tblKadry[Placówka],dFiltr,tblKadry[Aktywny_na_dzień],1),0) -> 10705 | F42: =IFERROR(AVERAGEIFS(tblKadry[Stawka_pełny_etat],tblKadry[Dział],B42,tblKadry[Płeć],"M",tblKadry[Placówka],dFiltr,tblKadry[Aktywny_na_dzień],1),0) -> 16617.5 | H42: Na czas nieokreślony | I42: =COUNTIFS(tblKadry[Typ_umowy],H42,tblKadry[Placówka],dFiltr,tblKadry[Aktywny_na_dzień],1) -> 25 | K42: =DATE(YEAR(pDataRaportu),1,1) -> 46023 | L42: =IF(K42>pDataRaportu,0,COUNTIFS(tblKadry[Data_zatrudnienia],">="&K42,tblKadry[Data_zatrudnienia],"<="&EOMONTH(K42,0),tblKadry[Placówka],dFiltr)) -> 0 | M42: =IF(K42>pDataRaportu,0,COUNTIFS(tblKadry[Status],"Zwolniony",tblKadry[Data_zwolnienia],">="&K42,tblKadry[Data_zwolnienia],"<="&EOMONTH(K42,0),tblKadry[Placówka],dFiltr)) -> 0
B43: =Parametry!C32 -> Kardiochirurgia | C43: =SUMIFS(tblKadry[Etat],tblKadry[Dział],B43,tblKadry[Placówka],dFiltr,tblKadry[Aktywny_na_dzień],1) -> 0 | D43: =SUMIFS(tblKadry[Koszt_pracodawcy_mies],tblKadry[Dział],B43,tblKadry[Placówka],dFiltr,tblKadry[Aktywny_na_dzień],1) -> 0 | E43: =IFERROR(AVERAGEIFS(tblKadry[Stawka_pełny_etat],tblKadry[Dział],B43,tblKadry[Płeć],"K",tblKadry[Placówka],dFiltr,tblKadry[Aktywny_na_dzień],1),0) -> 0 | F43: =IFERROR(AVERAGEIFS(tblKadry[Stawka_pełny_etat],tblKadry[Dział],B43,tblKadry[Płeć],"M",tblKadry[Placówka],dFiltr,tblKadry[Aktywny_na_dzień],1),0) -> 0 | H43: Na czas określony | I43: =COUNTIFS(tblKadry[Typ_umowy],H43,tblKadry[Placówka],dFiltr,tblKadry[Aktywny_na_dzień],1) -> 1 | K43: =DATE(YEAR(pDataRaportu),2,1) -> 46054 | L43: =IF(K43>pDataRaportu,0,COUNTIFS(tblKadry[Data_zatrudnienia],">="&K43,tblKadry[Data_zatrudnienia],"<="&EOMONTH(K43,0),tblKadry[Placówka],dFiltr)) -> 2 | M43: =IF(K43>pDataRaportu,0,COUNTIFS(tblKadry[Status],"Zwolniony",tblKadry[Data_zwolnienia],">="&K43,tblKadry[Data_zwolnienia],"<="&EOMONTH(K43,0),tblKadry[Placówka],dFiltr)) -> 1
B44: =Parametry!C33 -> Chirurgia naczyniowa | C44: =SUMIFS(tblKadry[Etat],tblKadry[Dział],B44,tblKadry[Placówka],dFiltr,tblKadry[Aktywny_na_dzień],1) -> 4 | D44: =SUMIFS(tblKadry[Koszt_pracodawcy_mies],tblKadry[Dział],B44,tblKadry[Placówka],dFiltr,tblKadry[Aktywny_na_dzień],1) -> 45278.976 | E44: =IFERROR(AVERAGEIFS(tblKadry[Stawka_pełny_etat],tblKadry[Dział],B44,tblKadry[Płeć],"K",tblKadry[Placówka],dFiltr,tblKadry[Aktywny_na_dzień],1),0) -> 9750 | F44: =IFERROR(AVERAGEIFS(tblKadry[Stawka_pełny_etat],tblKadry[Dział],B44,tblKadry[Płeć],"M",tblKadry[Placówka],dFiltr,tblKadry[Aktywny_na_dzień],1),0) -> 7870 | H44: Na okres próbny | I44: =COUNTIFS(tblKadry[Typ_umowy],H44,tblKadry[Placówka],dFiltr,tblKadry[Aktywny_na_dzień],1) -> 0 | K44: =DATE(YEAR(pDataRaportu),3,1) -> 46082 | L44: =IF(K44>pDataRaportu,0,COUNTIFS(tblKadry[Data_zatrudnienia],">="&K44,tblKadry[Data_zatrudnienia],"<="&EOMONTH(K44,0),tblKadry[Placówka],dFiltr)) -> 2 | M44: =IF(K44>pDataRaportu,0,COUNTIFS(tblKadry[Status],"Zwolniony",tblKadry[Data_zwolnienia],">="&K44,tblKadry[Data_zwolnienia],"<="&EOMONTH(K44,0),tblKadry[Placówka],dFiltr)) -> 0
B45: =Parametry!C34 -> Laboratorium | C45: =SUMIFS(tblKadry[Etat],tblKadry[Dział],B45,tblKadry[Placówka],dFiltr,tblKadry[Aktywny_na_dzień],1) -> 4.75 | D45: =SUMIFS(tblKadry[Koszt_pracodawcy_mies],tblKadry[Dział],B45,tblKadry[Placówka],dFiltr,tblKadry[Aktywny_na_dzień],1) -> 50713.185 | E45: =IFERROR(AVERAGEIFS(tblKadry[Stawka_pełny_etat],tblKadry[Dział],B45,tblKadry[Płeć],"K",tblKadry[Placówka],dFiltr,tblKadry[Aktywny_na_dzień],1),0) -> 7663.3333 | F45: =IFERROR(AVERAGEIFS(tblKadry[Stawka_pełny_etat],tblKadry[Dział],B45,tblKadry[Płeć],"M",tblKadry[Placówka],dFiltr,tblKadry[Aktywny_na_dzień],1),0) -> 8855 | K45: =DATE(YEAR(pDataRaportu),4,1) -> 46113 | L45: =IF(K45>pDataRaportu,0,COUNTIFS(tblKadry[Data_zatrudnienia],">="&K45,tblKadry[Data_zatrudnienia],"<="&EOMONTH(K45,0),tblKadry[Placówka],dFiltr)) -> 0 | M45: =IF(K45>pDataRaportu,0,COUNTIFS(tblKadry[Status],"Zwolniony",tblKadry[Data_zwolnienia],">="&K45,tblKadry[Data_zwolnienia],"<="&EOMONTH(K45,0),tblKadry[Placówka],dFiltr)) -> 0
B46: =Parametry!C35 -> Administracja | C46: =SUMIFS(tblKadry[Etat],tblKadry[Dział],B46,tblKadry[Placówka],dFiltr,tblKadry[Aktywny_na_dzień],1) -> 6.5 | D46: =SUMIFS(tblKadry[Koszt_pracodawcy_mies],tblKadry[Dział],B46,tblKadry[Placówka],dFiltr,tblKadry[Aktywny_na_dzień],1) -> 58660.182 | E46: =IFERROR(AVERAGEIFS(tblKadry[Stawka_pełny_etat],tblKadry[Dział],B46,tblKadry[Płeć],"K",tblKadry[Placówka],dFiltr,tblKadry[Aktywny_na_dzień],1),0) -> 6984.2857 | F46: =IFERROR(AVERAGEIFS(tblKadry[Stawka_pełny_etat],tblKadry[Dział],B46,tblKadry[Płeć],"M",tblKadry[Placówka],dFiltr,tblKadry[Aktywny_na_dzień],1),0) -> 0 | K46: =DATE(YEAR(pDataRaportu),5,1) -> 46143 | L46: =IF(K46>pDataRaportu,0,COUNTIFS(tblKadry[Data_zatrudnienia],">="&K46,tblKadry[Data_zatrudnienia],"<="&EOMONTH(K46,0),tblKadry[Placówka],dFiltr)) -> 0 | M46: =IF(K46>pDataRaportu,0,COUNTIFS(tblKadry[Status],"Zwolniony",tblKadry[Data_zwolnienia],">="&K46,tblKadry[Data_zwolnienia],"<="&EOMONTH(K46,0),tblKadry[Placówka],dFiltr)) -> 0
K47: =DATE(YEAR(pDataRaportu),6,1) -> 46174 | L47: =IF(K47>pDataRaportu,0,COUNTIFS(tblKadry[Data_zatrudnienia],">="&K47,tblKadry[Data_zatrudnienia],"<="&EOMONTH(K47,0),tblKadry[Placówka],dFiltr)) -> 0 | M47: =IF(K47>pDataRaportu,0,COUNTIFS(tblKadry[Status],"Zwolniony",tblKadry[Data_zwolnienia],">="&K47,tblKadry[Data_zwolnienia],"<="&EOMONTH(K47,0),tblKadry[Placówka],dFiltr)) -> 1
K48: =DATE(YEAR(pDataRaportu),7,1) -> 46204 | L48: =IF(K48>pDataRaportu,0,COUNTIFS(tblKadry[Data_zatrudnienia],">="&K48,tblKadry[Data_zatrudnienia],"<="&EOMONTH(K48,0),tblKadry[Placówka],dFiltr)) -> 0 | M48: =IF(K48>pDataRaportu,0,COUNTIFS(tblKadry[Status],"Zwolniony",tblKadry[Data_zwolnienia],">="&K48,tblKadry[Data_zwolnienia],"<="&EOMONTH(K48,0),tblKadry[Placówka],dFiltr)) -> 0
B49: Wskaźniki rotacji | K49: =DATE(YEAR(pDataRaportu),8,1) -> 46235 | L49: =IF(K49>pDataRaportu,0,COUNTIFS(tblKadry[Data_zatrudnienia],">="&K49,tblKadry[Data_zatrudnienia],"<="&EOMONTH(K49,0),tblKadry[Placówka],dFiltr)) -> 1 | M49: =IF(K49>pDataRaportu,0,COUNTIFS(tblKadry[Status],"Zwolniony",tblKadry[Data_zwolnienia],">="&K49,tblKadry[Data_zwolnienia],"<="&EOMONTH(K49,0),tblKadry[Placówka],dFiltr)) -> 0
B50: Początek roku | C50: =DATE(YEAR(pDataRaportu),1,1) -> 46023 | K50: =DATE(YEAR(pDataRaportu),9,1) -> 46266 | L50: =IF(K50>pDataRaportu,0,COUNTIFS(tblKadry[Data_zatrudnienia],">="&K50,tblKadry[Data_zatrudnienia],"<="&EOMONTH(K50,0),tblKadry[Placówka],dFiltr)) -> 0 | M50: =IF(K50>pDataRaportu,0,COUNTIFS(tblKadry[Status],"Zwolniony",tblKadry[Data_zwolnienia],">="&K50,tblKadry[Data_zwolnienia],"<="&EOMONTH(K50,0),tblKadry[Placówka],dFiltr)) -> 0
B51: Stan na początek roku | C51: =COUNTIFS(tblKadry[Placówka],dFiltr,tblKadry[Data_zatrudnienia],"<"&C50,tblKadry[Status],"Aktywny")+COUNTIFS(tblKadry[Placówka],dFiltr,tblKadry[Data_zatrudnienia],"<"&C50,tblKadry[Status],"Zwolniony",tblKadry[Data_zwolnienia],">="&C50) -> 23 | K51: =DATE(YEAR(pDataRaportu),10,1) -> 46296 | L51: =IF(K51>pDataRaportu,0,COUNTIFS(tblKadry[Data_zatrudnienia],">="&K51,tblKadry[Data_zatrudnienia],"<="&EOMONTH(K51,0),tblKadry[Placówka],dFiltr)) -> 0 | M51: =IF(K51>pDataRaportu,0,COUNTIFS(tblKadry[Status],"Zwolniony",tblKadry[Data_zwolnienia],">="&K51,tblKadry[Data_zwolnienia],"<="&EOMONTH(K51,0),tblKadry[Placówka],dFiltr)) -> 0
B52: Stan na dzień raportu | C52: =SUMIFS(tblKadry[Aktywny_na_dzień],tblKadry[Placówka],dFiltr) -> 26 | K52: =DATE(YEAR(pDataRaportu),11,1) -> 46327 | L52: =IF(K52>pDataRaportu,0,COUNTIFS(tblKadry[Data_zatrudnienia],">="&K52,tblKadry[Data_zatrudnienia],"<="&EOMONTH(K52,0),tblKadry[Placówka],dFiltr)) -> 0 | M52: =IF(K52>pDataRaportu,0,COUNTIFS(tblKadry[Status],"Zwolniony",tblKadry[Data_zwolnienia],">="&K52,tblKadry[Data_zwolnienia],"<="&EOMONTH(K52,0),tblKadry[Placówka],dFiltr)) -> 0
B53: Odejścia YTD | C53: =SUM(M42:M53) -> 2 | K53: =DATE(YEAR(pDataRaportu),12,1) -> 46357 | L53: =IF(K53>pDataRaportu,0,COUNTIFS(tblKadry[Data_zatrudnienia],">="&K53,tblKadry[Data_zatrudnienia],"<="&EOMONTH(K53,0),tblKadry[Placówka],dFiltr)) -> 0 | M53: =IF(K53>pDataRaportu,0,COUNTIFS(tblKadry[Status],"Zwolniony",tblKadry[Data_zwolnienia],">="&K53,tblKadry[Data_zwolnienia],"<="&EOMONTH(K53,0),tblKadry[Placówka],dFiltr)) -> 0
B54: Przyjęcia YTD | C54: =SUM(L42:L53) -> 5
B55: Rotacja YTD | C55: =IFERROR(C53/AVERAGE(C51,C52),0) -> 0.081632653

Sheet Parametry
A1: Parametry i założenia modelu
A2: Niebieska czcionka na żółtym tle = dane wejściowe (można zmieniać). Wszystkie pozostałe zakładki liczą się z tych komórek.
A4: Parametry ogólne | B4: Wartość
A5: Data raportu | B5: =DATE(2026,9,30) -> 46295
A6: Płaca minimalna 2026 (zł brutto, pełny etat) | B6: 4806
A7: Rok budżetu | B7: 2027
A9: Składki pracodawcy (% wynagrodzenia brutto) | B9: Stawka
A10: Ubezpieczenie emerytalne | B10: 0.0976
A11: Ubezpieczenie rentowe | B11: 0.065
A12: Ubezpieczenie wypadkowe (stawka przyjęta) | B12: 0.0167
A13: Fundusz Pracy | B13: 0.0245
A14: FGŚP | B14: 0.001
A15: PPK – wpłata podstawowa pracodawcy | B15: 0.015
A16: Razem narzut pracodawcy | B16: =SUM(B10:B15) -> 0.2198
A17: Uproszczenia: pominięto limit 30-krotności dla składek emerytalno-rentowych oraz zwolnienia z FP/FGŚP (wiek 55/60+). Wypadkowa wg stawki przyjętej – w praktyce ustalana indywidualnie przez ZUS.
A19: Widełki płacowe – siatka zaszeregowania (pełny etat, zł brutto / mies.)
A20: Grupa | B20: Opis grupy | C20: Min | D20: Max | E20: Środek | F20: Podwyżka 2027 %
A21: G1 | B21: Pracownicy pomocniczy | C21: 4806 | D21: 5800 | E21: =(tblWidelki[[#This Row],[Min]]+tblWidelki[[#This Row],[Max]])/2 -> 5303 | F21: 0.06
A22: G2 | B22: Technicy / referenci | C22: 5500 | D22: 7500 | E22: =(tblWidelki[[#This Row],[Min]]+tblWidelki[[#This Row],[Max]])/2 -> 6500 | F22: 0.05
A23: G3 | B23: Specjaliści (pielęgniarki, diagności) | C23: 7000 | D23: 10000 | E23: =(tblWidelki[[#This Row],[Min]]+tblWidelki[[#This Row],[Max]])/2 -> 8500 | F23: 0.05
A24: G4 | B24: Starsi specjaliści / koordynatorzy | C24: 9000 | D24: 13000 | E24: =(tblWidelki[[#This Row],[Min]]+tblWidelki[[#This Row],[Max]])/2 -> 11000 | F24: 0.04
A25: G5 | B25: Lekarze | C25: 13000 | D25: 19000 | E25: =(tblWidelki[[#This Row],[Min]]+tblWidelki[[#This Row],[Max]])/2 -> 16000 | F25: 0.04
A26: G6 | B26: Lekarze specjaliści / kierownicy | C26: 17000 | D26: 24000 | E26: =(tblWidelki[[#This Row],[Min]]+tblWidelki[[#This Row],[Max]])/2 -> 20500 | F26: 0.03
A29: Słowniki (listy rozwijane i raporty)
A30: Placówka | C30: Dział | E30: Filtr dashboardu
A31: Katowice | C31: Kardiologia | E31: Wszystkie
A32: Kraków | C32: Kardiochirurgia | E32: =A31 -> Katowice
A33: Ustroń | C33: Chirurgia naczyniowa | E33: =A32 -> Kraków
A34: Bielsko-Biała | C34: Laboratorium | E34: =A33 -> Ustroń
C35: Administracja | E35: =A34 -> Bielsko-Biała

Sheet Dane_Kadrowe
A1: Dane kadrowo-płacowe – eksport z systemu HR (dane fikcyjne)
A2: Kolumny A–M: dane źródłowe (eksport). Kolumny N–V (szare nagłówki): kolumny wyliczane formułami. Dane spseudonimizowane – tylko ID pracownika (RODO).
A3: ID_Pracownika | B3: Placówka | C3: Dział | D3: Stanowisko | E3: Grupa | F3: Płeć | G3: Data_zatrudnienia | H3: Typ_umowy | I3: Etat | J3: Wynagrodzenie_zasadnicze | K3: Dodatek_funkcyjny | L3: Status | M3: Data_zwolnienia | N3: Brutto_mies | O3: Stawka_pełny_etat | P3: Aktywny_na_dzień | Q3: Staż_lat | R3: Koszt_pracodawcy_mies | S3: Środek_widełek | T3: Compa_ratio | U3: Pozycja_w_widełkach | V3: Uwagi_QC
A4: P1112 | B4: Kraków | C4: Kardiologia | D4: Pielęgniarka / pielęgniarz | E4: G3 | F4: K | G4: 42644 | H4: Na czas nieokreślony | I4: 1 | K4: 0 | L4: Aktywny | N4: =tblKadry[[#This Row],[Wynagrodzenie_zasadnicze]]+tblKadry[[#This Row],[Dodatek_funkcyjny]] -> 0 | O4: =IF(OR(tblKadry[[#This Row],[Wynagrodzenie_zasadnicze]]="",tblKadry[[#This Row],[Etat]]=0),"",tblKadry[[#This Row],[Wynagrodzenie_zasadnicze]]/tblKadry[[#This Row],[Etat]]) | P4: =IF(AND(tblKadry[[#This Row],[Status]]="Aktywny",tblKadry[[#This Row],[Data_zatrudnienia]]<=pDataRaportu),1,0) -> 1 | Q4: =IF(tblKadry[[#This Row],[Data_zatrudnienia]]>pDataRaportu,0,ROUND(YEARFRAC(tblKadry[[#This Row],[Data_zatrudnienia]],IF(tblKadry[[#This Row],[Data_zwolnienia]]="",pDataRaportu,tblKadry[[#This Row],[Data_zwolnienia]])),1)) -> 10 | R4: =tblKadry[[#This Row],[Brutto_mies]]*(1+pNarzut) -> 0 | S4: =_xlfn.XLOOKUP(tblKadry[[#This Row],[Grupa]],tblWidelki[Grupa],tblWidelki[Środek],"") -> 8500 | T4: =IF(tblKadry[[#This Row],[Stawka_pełny_etat]]="","",tblKadry[[#This Row],[Stawka_pełny_etat]]/tblKadry[[#This Row],[Środek_widełek]]) | U4: =IF(tblKadry[[#This Row],[Stawka_pełny_etat]]="","",IF(tblKadry[[#This Row],[Stawka_pełny_etat]]<_xlfn.XLOOKUP(tblKadry[[#This Row],[Grupa]],tblWidelki[Grupa],tblWidelki[Min]),"Poniżej",IF(tblKadry[[#This Row],[Stawka_pełny_etat]]>_xlfn.XLOOKUP(tblKadry[[#This Row],[Grupa]],tblWidelki[Grupa],tblWidelki[Max]),"Powyżej","W widełkach"))) | V4: =_xlfn.TEXTJOIN("; ",TRUE,IF(COUNTIF(tblKadry[ID_Pracownika],tblKadry[[#This Row],[ID_Pracownika]])>1,"Duplikat ID",""),IF(tblKadry[[#This Row],[Dział]]="","Brak działu",""),IF(tblKadry[[#This Row],[Wynagrodzenie_zasadnicze]]="","Brak wynagrodzenia",""),IF(AND(tblKadry[[#This Row],[Wynagrodzenie_zasadnicze]]<>"",tblKadry[[#This Row],[Brutto_mies]]<pPlacaMin*tblKadry[[#This Row],[Etat]]),"Poniżej płacy minimalnej",""),IF(OR(tblKadry[[#This Row],[Etat]]<=0,tblKadry[[#This Row],[Etat]]>1),"Nieprawidłowy etat",""),IF(tblKadry[[#This Row],[Data_zatrudnienia]]>pDataRaportu,"Data zatrudnienia w przyszłości",""),IF(AND(tblKadry[[#This Row],[Status]]="Zwolniony",tblKadry[[#This Row],[Data_zwolnienia]]=""),"Brak daty zwolnienia",""),IF(AND(tblKadry[[#This Row],[Status]]="Aktywny",tblKadry[[#This Row],[Data_zwolnienia]]<>""),"Aktywny z datą zwolnienia",""),IF(AND(tblKadry[[#This Row],[Status]]="Aktywny",tblKadry[[#This Row],[Typ_umowy]]="Na czas określony",tblKadry[[#This Row],[Staż_lat]]>2.75),"Umowa terminowa > 33 mies. (art. 25¹ KP)",""),IF(AND(tblKadry[[#This Row],[Status]]="Aktywny",tblKadry[[#This Row],[Typ_umowy]]="Na okres próbny",tblKadry[[#This Row],[Staż_lat]]>0.25),"Okres próbny > 3 mies. (art. 25 KP)","")) -> Brak wynagrodzenia
A5: P1126 | B5: Katowice | C5: Kardiochirurgia | D5: Lekarz specjalista | E5: G6 | F5: K | G5: 39651 | H5: Na czas nieokreślony | I5: 1 | J5: 25750 | K5: 0 | L5: Aktywny | N5: =tblKadry[[#This Row],[Wynagrodzenie_zasadnicze]]+tblKadry[[#This Row],[Dodatek_funkcyjny]] -> 25750 | O5: =IF(OR(tblKadry[[#This Row],[Wynagrodzenie_zasadnicze]]="",tblKadry[[#This Row],[Etat]]=0),"",tblKadry[[#This Row],[Wynagrodzenie_zasadnicze]]/tblKadry[[#This Row],[Etat]]) -> 25750 | P5: =IF(AND(tblKadry[[#This Row],[Status]]="Aktywny",tblKadry[[#This Row],[Data_zatrudnienia]]<=pDataRaportu),1,0) -> 1 | Q5: =IF(tblKadry[[#This Row],[Data_zatrudnienia]]>pDataRaportu,0,ROUND(YEARFRAC(tblKadry[[#This Row],[Data_zatrudnienia]],IF(tblKadry[[#This Row],[Data_zwolnienia]]="",pDataRaportu,tblKadry[[#This Row],[Data_zwolnienia]])),1)) -> 18.2 | R5: =tblKadry[[#This Row],[Brutto_mies]]*(1+pNarzut) -> 31409.85 | S5: =_xlfn.XLOOKUP(tblKadry[[#This Row],[Grupa]],tblWidelki[Grupa],tblWidelki[Środek],"") -> 20500 | T5: =IF(tblKadry[[#This Row],[Stawka_pełny_etat]]="","",tblKadry[[#This Row],[Stawka_pełny_etat]]/tblKadry[[#This Row],[Środek_widełek]]) -> 1.2560976 | U5: =IF(tblKadry[[#This Row],[Stawka_pełny_etat]]="","",IF(tblKadry[[#This Row],[Stawka_pełny_etat]]<_xlfn.XLOOKUP(tblKadry[[#This Row],[Grupa]],tblWidelki[Grupa],tblWidelki[Min]),"Poniżej",IF(tblKadry[[#This Row],[Stawka_pełny_etat]]>_xlfn.XLOOKUP(tblKadry[[#This Row],[Grupa]],tblWidelki[Grupa],tblWidelki[Max]),"Powyżej","W widełkach"))) -> Powyżej | V5: =_xlfn.TEXTJOIN("; ",TRUE,IF(COUNTIF(tblKadry[ID_Pracownika],tblKadry[[#This Row],[ID_Pracownika]])>1,"Duplikat ID",""),IF(tblKadry[[#This Row],[Dział]]="","Brak działu",""),IF(tblKadry[[#This Row],[Wynagrodzenie_zasadnicze]]="","Brak wynagrodzenia",""),IF(AND(tblKadry[[#This Row],[Wynagrodzenie_zasadnicze]]<>"",tblKadry[[#This Row],[Brutto_mies]]<pPlacaMin*tblKadry[[#This Row],[Etat]]),"Poniżej płacy minimalnej",""),IF(OR(tblKadry[[#This Row],[Etat]]<=0,tblKadry[[#This Row],[Etat]]>1),"Nieprawidłowy etat",""),IF(tblKadry[[#This Row],[Data_zatrudnienia]]>pDataRaportu,"Data zatrudnienia w przyszłości",""),IF(AND(tblKadry[[#This Row],[Status]]="Zwolniony",tblKadry[[#This Row],[Data_zwolnienia]]=""),"Brak daty zwolnienia",""),IF(AND(tblKadry[[#This Row],[Status]]="Aktywny",tblKadry[[#This Row],[Data_zwolnienia]]<>""),"Aktywny z datą zwolnienia",""),IF(AND(tblKadry[[#This Row],[Status]]="Aktywny",tblKadry[[#This Row],[Typ_umowy]]="Na czas określony",tblKadry[[#This Row],[Staż_lat]]>2.75),"Umowa terminowa > 33 mies. (art. 25¹ KP)",""),IF(AND(tblKadry[[#This Row],[Status]]="Aktywny",tblKadry[[#This Row],[Typ_umowy]]="Na okres próbny",tblKadry[[#This Row],[Staż_lat]]>0.25),"Okres próbny > 3 mies. (art. 25 KP)",""))
A6: P1011 | B6: Katowice | C6: Chirurgia naczyniowa | D6: Lekarz specjalista | E6: G6 | F6: K | G6: 43833 | H6: Na czas nieokreślony | I6: 1 | J6: 25270 | K6: 0 | L6: Zwolniony | M6: 46293 | N6: =tblKadry[[#This Row],[Wynagrodzenie_zasadnicze]]+tblKadry[[#This Row],[Dodatek_funkcyjny]] -> 25270 | O6: =IF(OR(tblKadry[[#This Row],[Wynagrodzenie_zasadnicze]]="",tblKadry[[#This Row],[Etat]]=0),"",tblKadry[[#This Row],[Wynagrodzenie_zasadnicze]]/tblKadry[[#This Row],[Etat]]) -> 25270 | P6: =IF(AND(tblKadry[[#This Row],[Status]]="Aktywny",tblKadry[[#This Row],[Data_zatrudnienia]]<=pDataRaportu),1,0) -> 0 | Q6: =IF(tblKadry[[#This Row],[Data_zatrudnienia]]>pDataRaportu,0,ROUND(YEARFRAC(tblKadry[[#This Row],[Data_zatrudnienia]],IF(tblKadry[[#This Row],[Data_zwolnienia]]="",pDataRaportu,tblKadry[[#This Row],[Data_zwolnienia]])),1)) -> 6.7 | R6: =tblKadry[[#This Row],[Brutto_mies]]*(1+pNarzut) -> 30824.346 | S6: =_xlfn.XLOOKUP(tblKadry[[#This Row],[Grupa]],tblWidelki[Grupa],tblWidelki[Środek],"") -> 20500 | T6: =IF(tblKadry[[#This Row],[Stawka_pełny_etat]]="","",tblKadry[[#This Row],[Stawka_pełny_etat]]/tblKadry[[#This Row],[Środek_widełek]]) -> 1.2326829 | U6: =IF(tblKadry[[#This Row],[Stawka_pełny_etat]]="","",IF(tblKadry[[#This Row],[Stawka_pełny_etat]]<_xlfn.XLOOKUP(tblKadry[[#This Row],[Grupa]],tblWidelki[Grupa],tblWidelki[Min]),"Poniżej",IF(tblKadry[[#This Row],[Stawka_pełny_etat]]>_xlfn.XLOOKUP(tblKadry[[#This Row],[Grupa]],tblWidelki[Grupa],tblWidelki[Max]),"Powyżej","W widełkach"))) -> Powyżej | V6: =_xlfn.TEXTJOIN("; ",TRUE,IF(COUNTIF(tblKadry[ID_Pracownika],tblKadry[[#This Row],[ID_Pracownika]])>1,"Duplikat ID",""),IF(tblKadry[[#This Row],[Dział]]="","Brak działu",""),IF(tblKadry[[#This Row],[Wynagrodzenie_zasadnicze]]="","Brak wynagrodzenia",""),IF(AND(tblKadry[[#This Row],[Wynagrodzenie_zasadnicze]]<>"",tblKadry[[#This Row],[Brutto_mies]]<pPlacaMin*tblKadry[[#This Row],[Etat]]),"Poniżej płacy minimalnej",""),IF(OR(tblKadry[[#This Row],[Etat]]<=0,tblKadry[[#This Row],[Etat]]>1),"Nieprawidłowy etat",""),IF(tblKadry[[#This Row],[Data_zatrudnienia]]>pDataRaportu,"Data zatrudnienia w przyszłości",""),IF(AND(tblKadry[[#This Row],[Status]]="Zwolniony",tblKadry[[#This Row],[Data_zwolnienia]]=""),"Brak daty zwolnienia",""),IF(AND(tblKadry[[#This Row],[Status]]="Aktywny",tblKadry[[#This Row],[Data_zwolnienia]]<>""),"Aktywny z datą zwolnienia",""),IF(AND(tblKadry[[#This Row],[Status]]="Aktywny",tblKadry[[#This Row],[Typ_umowy]]="Na czas określony",tblKadry[[#This Row],[Staż_lat]]>2.75),"Umowa terminowa > 33 mies. (art. 25¹ KP)",""),IF(AND(tblKadry[[#This Row],[Status]]="Aktywny",tblKadry[[#This Row],[Typ_umowy]]="Na okres próbny",tblKadry[[#This Row],[Staż_lat]]>0.25),"Okres próbny > 3 mies. (art. 25 KP)",""))
A7: P1076 | B7: Ustroń | C7: Kardiologia | D7: Lekarz specjalista | E7: G6 | F7: M | G7: 40950 | H7: Na czas nieokreślony | I7: 1 | J7: 24850 | K7: 0 | L7: Aktywny | N7: =tblKadry[[#This Row],[Wynagrodzenie_zasadnicze]]+tblKadry[[#This Row],[Dodatek_funkcyjny]] -> 24850 | O7: =IF(OR(tblKadry[[#This Row],[Wynagrodzenie_zasadnicze]]="",tblKadry[[#This Row],[Etat]]=0),"",tblKadry[[#This Row],[Wynagrodzenie_zasadnicze]]/tblKadry[[#This Row],[Etat]]) -> 24850 | P7: =IF(AND(tblKadry[[#This Row],[Status]]="Aktywny",tblKadry[[#This Row],[Data_zatrudnienia]]<=pDataRaportu),1,0) -> 1 | Q7: =IF(tblKadry[[#This Row],[Data_zatrudnienia]]>pDataRaportu,0,ROUND(YEARFRAC(tblKadry[[#This Row],[Data_zatrudnienia]],IF(tblKadry[[#This Row],[Data_zwolnienia]]="",pDataRaportu,tblKadry[[#This Row],[Data_zwolnienia]])),1)) -> 14.6 | R7: =tblKadry[[#This Row],[Brutto_mies]]*(1+pNarzut) -> 30312.03 | S7: =_xlfn.XLOOKUP(tblKadry[[#This Row],[Grupa]],tblWidelki[Grupa],tblWidelki[Środek],"") -> 20500 | T7: =IF(tblKadry[[#This Row],[Stawka_pełny_etat]]="","",tblKadry[[#This Row],[Stawka_pełny_etat]]/tblKadry[[#This Row],[Środek_widełek]]) -> 1.2121951 | U7: =IF(tblKadry[[#This Row],[Stawka_pełny_etat]]="","",IF(tblKadry[[#This Row],[Stawka_pełny_etat]]<_xlfn.XLOOKUP(tblKadry[[#This Row],[Grupa]],tblWidelki[Grupa],tblWidelki[Min]),"Poniżej",IF(tblKadry[[#This Row],[Stawka_pełny_etat]]>_xlfn.XLOOKUP(tblKadry[[#This Row],[Grupa]],tblWidelki[Grupa],tblWidelki[Max]),"Powyżej","W widełkach"))) -> Powyżej | V7: =_xlfn.TEXTJOIN("; ",TRUE,IF(COUNTIF(tblKadry[ID_Pracownika],tblKadry[[#This Row],[ID_Pracownika]])>1,"Duplikat ID",""),IF(tblKadry[[#This Row],[Dział]]="","Brak działu",""),IF(tblKadry[[#This Row],[Wynagrodzenie_zasadnicze]]="","Brak wynagrodzenia",""),IF(AND(tblKadry[[#This Row],[Wynagrodzenie_zasadnicze]]<>"",tblKadry[[#This Row],[Brutto_mies]]<pPlacaMin*tblKadry[[#This Row],[Etat]]),"Poniżej płacy minimalnej",""),IF(OR(tblKadry[[#This Row],[Etat]]<=0,tblKadry[[#This Row],[Etat]]>1),"Nieprawidłowy etat",""),IF(tblKadry[[#This Row],[Data_zatrudnienia]]>pDataRaportu,"Data zatrudnienia w przyszłości",""),IF(AND(tblKadry[[#This Row],[Status]]="Zwolniony",tblKadry[[#This Row],[Data_zwolnienia]]=""),"Brak daty zwolnienia",""),IF(AND(tblKadry[[#This Row],[Status]]="Aktywny",tblKadry[[#This Row],[Data_zwolnienia]]<>""),"Aktywny z datą zwolnienia",""),IF(AND(tblKadry[[#This Row],[Status]]="Aktywny",tblKadry[[#This Row],[Typ_umowy]]="Na czas określony",tblKadry[[#This Row],[Staż_lat]]>2.75),"Umowa terminowa > 33 mies. (art. 25¹ KP)",""),IF(AND(tblKadry[[#This Row],[Status]]="Aktywny",tblKadry[[#This Row],[Typ_umowy]]="Na okres próbny",tblKadry[[#This Row],[Staż_lat]]>0.25),"Okres próbny > 3 mies. (art. 25 KP)",""))
A8: P1114 | B8: Bielsko-Biała | C8: Kardiochirurgia | D8: Lekarz specjalista | E8: G6 | F8: M | G8: 39978 | H8: Na czas określony | I8: 1 | J8: 23690 | K8: 0 | L8: Zwolniony | M8: 46081 | N8: =tblKadry[[#This Row],[Wynagrodzenie_zasadnicze]]+tblKadry[[#This Row],[Dodatek_funkcyjny]] -> 23690 | O8: =IF(OR(tblKadry[[#This Row],[Wynagrodzenie_zasadnicze]]="",tblKadry[[#This Row],[Etat]]=0),"",tblKadry[[#This Row],[Wynagrodzenie_zasadnicze]]/tblKadry[[#This Row],[Etat]]) -> 23690 | P8: =IF(AND(tblKadry[[#This Row],[Status]]="Aktywny",tblKadry[[#This Row],[Data_zatrudnienia]]<=pDataRaportu),1,0) -> 0 | Q8: =IF(tblKadry[[#This Row],[Data_zatrudnienia]]>pDataRaportu,0,ROUND(YEARFRAC(tblKadry[[#This Row],[Data_zatrudnienia]],IF(tblKadry[[#This Row],[Data_zwolnienia]]="",pDataRaportu,tblKadry[[#This Row],[Data_zwolnienia]])),1)) -> 16.7 | R8: =tblKadry[[#This Row],[Brutto_mies]]*(1+pNarzut) -> 28897.062 | S8: =_xlfn.XLOOKUP(tblKadry[[#This Row],[Grupa]],tblWidelki[Grupa],tblWidelki[Środek],"") -> 20500 | T8: =IF(tblKadry[[#This Row],[Stawka_pełny_etat]]="","",tblKadry[[#This Row],[Stawka_pełny_etat]]/tblKadry[[#This Row],[Środek_widełek]]) -> 1.1556098 | U8: =IF(tblKadry[[#This Row],[Stawka_pełny_etat]]="","",IF(tblKadry[[#This Row],[Stawka_pełny_etat]]<_xlfn.XLOOKUP(tblKadry[[#This Row],[Grupa]],tblWidelki[Grupa],tblWidelki[Min]),"Poniżej",IF(tblKadry[[#This Row],[Stawka_pełny_etat]]>_xlfn.XLOOKUP(tblKadry[[#This Row],[Grupa]],tblWidelki[Grupa],tblWidelki[Max]),"Powyżej","W widełkach"))) -> W widełkach | V8: =_xlfn.TEXTJOIN("; ",TRUE,IF(COUNTIF(tblKadry[ID_Pracownika],tblKadry[[#This Row],[ID_Pracownika]])>1,"Duplikat ID",""),IF(tblKadry[[#This Row],[Dział]]="","Brak działu",""),IF(tblKadry[[#This Row],[Wynagrodzenie_zasadnicze]]="","Brak wynagrodzenia",""),IF(AND(tblKadry[[#This Row],[Wynagrodzenie_zasadnicze]]<>"",tblKadry[[#This Row],[Brutto_mies]]<pPlacaMin*tblKadry[[#This Row],[Etat]]),"Poniżej płacy minimalnej",""),IF(OR(tblKadry[[#This Row],[Etat]]<=0,tblKadry[[#This Row],[Etat]]>1),"Nieprawidłowy etat",""),IF(tblKadry[[#This Row],[Data_zatrudnienia]]>pDataRaportu,"Data zatrudnienia w przyszłości",""),IF(AND(tblKadry[[#This Row],[Status]]="Zwolniony",tblKadry[[#This Row],[Data_zwolnienia]]=""),"Brak daty zwolnienia",""),IF(AND(tblKadry[[#This Row],[Status]]="Aktywny",tblKadry[[#This Row],[Data_zwolnienia]]<>""),"Aktywny z datą zwolnienia",""),IF(AND(tblKadry[[#This Row],[Status]]="Aktywny",tblKadry[[#This Row],[Typ_umowy]]="Na czas określony",tblKadry[[#This Row],[Staż_lat]]>2.75),"Umowa terminowa > 33 mies. (art. 25¹ KP)",""),IF(AND(tblKadry[[#This Row],[Status]]="Aktywny",tblKadry[[#This Row],[Typ_umowy]]="Na okres próbny",tblKadry[[#This Row],[Staż_lat]]>0.25),"Okres próbny > 3 mies. (art. 25 KP)",""))
A9: P1017 | B9: Katowice | C9: Chirurgia naczyniowa | D9: Lekarz specjalista | E9: G6 | F9: M | G9: 40394 | H9: Na czas nieokreślony | I9: 1 | J9: 23320 | K9: 0 | L9: Aktywny | N9: =tblKadry[[#This Row],[Wynagrodzenie_zasadnicze]]+tblKadry[[#This Row],[Dodatek_funkcyjny]] -> 23320 | O9: =IF(OR(tblKadry[[#This Row],[Wynagrodzenie_zasadnicze]]="",tblKadry[[#This Row],[Etat]]=0),"",tblKadry[[#This Row],[Wynagrodzenie_zasadnicze]]/tblKadry[[#This Row],[Etat]]) -> 23320 | P9: =IF(AND(tblKadry[[#This Row],[Status]]="Aktywny",tblKadry[[#This Row],[Data_zatrudnienia]]<=pDataRaportu),1,0) -> 1 | Q9: =IF(tblKadry[[#This Row],[Data_zatrudnienia]]>pDataRaportu,0,ROUND(YEARFRAC(tblKadry[[#This Row],[Data_zatrudnienia]],IF(tblKadry[[#This Row],[Data_zwolnienia]]="",pDataRaportu,tblKadry[[#This Row],[Data_zwolnienia]])),1)) -> 16.2 | R9: =tblKadry[[#This Row],[Brutto_mies]]*(1+pNarzut) -> 28445.736 | S9: =_xlfn.XLOOKUP(tblKadry[[#This Row],[Grupa]],tblWidelki[Grupa],tblWidelki[Środek],"") -> 20500 | T9: =IF(tblKadry[[#This Row],[Stawka_pełny_etat]]="","",tblKadry[[#This Row],[Stawka_pełny_etat]]/tblKadry[[#This Row],[Środek_widełek]]) -> 1.137561 | U9: =IF(tblKadry[[#This Row],[Stawka_pełny_etat]]="","",IF(tblKadry[[#This Row],[Stawka_pełny_etat]]<_xlfn.XLOOKUP(tblKadry[[#This Row],[Grupa]],tblWidelki[Grupa],tblWidelki[Min]),"Poniżej",IF(tblKadry[[#This Row],[Stawka_pełny_etat]]>_xlfn.XLOOKUP(tblKadry[[#This Row],[Grupa]],tblWidelki[Grupa],tblWidelki[Max]),"Powyżej","W widełkach"))) -> W widełkach | V9: =_xlfn.TEXTJOIN("; ",TRUE,IF(COUNTIF(tblKadry[ID_Pracownika],tblKadry[[#This Row],[ID_Pracownika]])>1,"Duplikat ID",""),IF(tblKadry[[#This Row],[Dział]]="","Brak działu",""),IF(tblKadry[[#This Row],[Wynagrodzenie_zasadnicze]]="","Brak wynagrodzenia",""),IF(AND(tblKadry[[#This Row],[Wynagrodzenie_zasadnicze]]<>"",tblKadry[[#This Row],[Brutto_mies]]<pPlacaMin*tblKadry[[#This Row],[Etat]]),"Poniżej płacy minimalnej",""),IF(OR(tblKadry[[#This Row],[Etat]]<=0,tblKadry[[#This Row],[Etat]]>1),"Nieprawidłowy etat",""),IF(tblKadry[[#This Row],[Data_zatrudnienia]]>pDataRaportu,"Data zatrudnienia w przyszłości",""),IF(AND(tblKadry[[#This Row],[Status]]="Zwolniony",tblKadry[[#This Row],[Data_zwolnienia]]=""),"Brak daty zwolnienia",""),IF(AND(tblKadry[[#This Row],[Status]]="Aktywny",tblKadry[[#This Row],[Data_zwolnienia]]<>""),"Aktywny z datą zwolnienia",""),IF(AND(tblKadry[[#This Row],[Status]]="Aktywny",tblKadry[[#This Row],[Typ_umowy]]="Na czas określony",tblKadry[[#This Row],[Staż_lat]]>2.75),"Umowa terminowa > 33 mies. (art. 25¹ KP)",""),IF(AND(tblKadry[[#This Row],[Status]]="Aktywny",tblKadry[[#This Row],[Typ_umowy]]="Na okres próbny",tblKadry[[#This Row],[Staż_lat]]>0.25),"Okres próbny > 3 mies. (art. 25 KP)",""))
A10: P1093 | B10: Kraków | C10: Kardiologia | D10: Lekarz specjalista | E10: G6 | F10: M | G10: 40030 | H10: Na czas nieokreślony | I10: 1 | J10: 22690 | K10: 0 | L10: Aktywny | N10: =tblKadry[[#This Row],[Wynagrodzenie_zasadnicze]]+tblKadry[[#This Row],[Dodatek_funkcyjny]] -> 22690 | O10: =IF(OR(tblKadry[[#This Row],[Wynagrodzenie_zasadnicze]]="",tblKadry[[#This Row],[Etat]]=0),"",tblKadry[[#This Row],[Wynagrodzenie_zasadnicze]]/tblKadry[[#This Row],[Etat]]) -> 22690 | P10: =IF(AND(tblKadry[[#This Row],[Status]]="Aktywny",tblKadry[[#This Row],[Data_zatrudnienia]]<=pDataRaportu),1,0) -> 1 | Q10: =IF(tblKadry[[#This Row],[Data_zatrudnienia]]>pDataRaportu,0,ROUND(YEARFRAC(tblKadry[[#This Row],[Data_zatrudnienia]],IF(tblKadry[[#This Row],[Data_zwolnienia]]="",pDataRaportu,tblKadry[[#This Row],[Data_zwolnienia]])),1)) -> 17.2 | R10: =tblKadry[[#This Row],[Brutto_mies]]*(1+pNarzut) -> 27677.262 | S10: =_xlfn.XLOOKUP(tblKadry[[#This Row],[Grupa]],tblWidelki[Grupa],tblWidelki[Środek],"") -> 20500 | T10: =IF(tblKadry[[#This Row],[Stawka_pełny_etat]]="","",tblKadry[[#This Row],[Stawka_pełny_etat]]/tblKadry[[#This Row],[Środek_widełek]]) -> 1.1068293 | U10: =IF(tblKadry[[#This Row],[Stawka_pełny_etat]]="","",IF(tblKadry[[#This Row],[Stawka_pełny_etat]]<_xlfn.XLOOKUP(tblKadry[[#This Row],[Grupa]],tblWidelki[Grupa],tblWidelki[Min]),"Poniżej",IF(tblKadry[[#This Row],[Stawka_pełny_etat]]>_xlfn.XLOOKUP(tblKadry[[#This Row],[Grupa]],tblWidelki[Grupa],tblWidelki[Max]),"Powyżej","W widełkach"))) -> W widełkach | V10: =_xlfn.TEXTJOIN("; ",TRUE,IF(COUNTIF(tblKadry[ID_Pracownika],tblKadry[[#This Row],[ID_Pracownika]])>1,"Duplikat ID",""),IF(tblKadry[[#This Row],[Dział]]="","Brak działu",""),IF(tblKadry[[#This Row],[Wynagrodzenie_zasadnicze]]="","Brak wynagrodzenia",""),IF(AND(tblKadry[[#This Row],[Wynagrodzenie_zasadnicze]]<>"",tblKadry[[#This Row],[Brutto_mies]]<pPlacaMin*tblKadry[[#This Row],[Etat]]),"Poniżej płacy minimalnej",""),IF(OR(tblKadry[[#This Row],[Etat]]<=0,tblKadry[[#This Row],[Etat]]>1),"Nieprawidłowy etat",""),IF(tblKadry[[#This Row],[Data_zatrudnienia]]>pDataRaportu,"Data zatrudnienia w przyszłości",""),IF(AND(tblKadry[[#This Row],[Status]]="Zwolniony",tblKadry[[#This Row],[Data_zwolnienia]]=""),"Brak daty zwolnienia",""),IF(AND(tblKadry[[#This Row],[Status]]="Aktywny",tblKadry[[#This Row],[Data_zwolnienia]]<>""),"Aktywny z datą zwolnienia",""),IF(AND(tblKadry[[#This Row],[Status]]="Aktywny",tblKadry[[#This Row],[Typ_umowy]]="Na czas określony",tblKadry[[#This Row],[Staż_lat]]>2.75),"Umowa terminowa > 33 mies. (art. 25¹ KP)",""),IF(AND(tblKadry[[#This Row],[Status]]="Aktywny",tblKadry[[#This Row],[Typ_umowy]]="Na okres próbny",tblKadry[[#This Row],[Staż_lat]]>0.25),"Okres próbny > 3 mies. (art. 25 KP)",""))
A11: P1008 | B11: Kraków | C11: Kardiochirurgia | D11: Lekarz specjalista | E11: G6 | F11: M | G11: 44429 | H11: Na czas nieokreślony | I11: 0.75 | J11: 16890 | K11: 0 | L11: Aktywny | N11: =tblKadry[[#This Row],[Wynagrodzenie_zasadnicze]]+tblKadry[[#This Row],[Dodatek_funkcyjny]] -> 16890 | O11: =IF(OR(tblKadry[[#This Row],[Wynagrodzenie_zasadnicze]]="",tblKadry[[#This Row],[Etat]]=0),"",tblKadry[[#This Row],[Wynagrodzenie_zasadnicze]]/tblKadry[[#This Row],[Etat]]) -> 22520 | P11: =IF(AND(tblKadry[[#This Row],[Status]]="Aktywny",tblKadry[[#This Row],[Data_zatrudnienia]]<=pDataRaportu),1,0) -> 1 | Q11: =IF(tblKadry[[#This Row],[Data_zatrudnienia]]>pDataRaportu,0,ROUND(YEARFRAC(tblKadry[[#This Row],[Data_zatrudnienia]],IF(tblKadry[[#This Row],[Data_zwolnienia]]="",pDataRaportu,tblKadry[[#This Row],[Data_zwolnienia]])),1)) -> 5.1 | R11: =tblKadry[[#This Row],[Brutto_mies]]*(1+pNarzut) -> 20602.422 | S11: =_xlfn.XLOOKUP(tblKadry[[#This Row],[Grupa]],tblWidelki[Grupa],tblWidelki[Środek],"") -> 20500 | T11: =IF(tblKadry[[#This Row],[Stawka_pełny_etat]]="","",tblKadry[[#This Row],[Stawka_pełny_etat]]/tblKadry[[#This Row],[Środek_widełek]]) -> 1.0985366 | U11: =IF(tblKadry[[#This Row],[Stawka_pełny_etat]]="","",IF(tblKadry[[#This Row],[Stawka_pełny_etat]]<_xlfn.XLOOKUP(tblKadry[[#This Row],[Grupa]],tblWidelki[Grupa],tblWidelki[Min]),"Poniżej",IF(tblKadry[[#This Row],[Stawka_pełny_etat]]>_xlfn.XLOOKUP(tblKadry[[#This Row],[Grupa]],tblWidelki[Grupa],tblWidelki[Max]),"Powyżej","W widełkach"))) -> W widełkach | V11: =_xlfn.TEXTJOIN("; ",TRUE,IF(COUNTIF(tblKadry[ID_Pracownika],tblKadry[[#This Row],[ID_Pracownika]])>1,"Duplikat ID",""),IF(tblKadry[[#This Row],[Dział]]="","Brak działu",""),IF(tblKadry[[#This Row],[Wynagrodzenie_zasadnicze]]="","Brak wynagrodzenia",""),IF(AND(tblKadry[[#This Row],[Wynagrodzenie_zasadnicze]]<>"",tblKadry[[#This Row],[Brutto_mies]]<pPlacaMin*tblKadry[[#This Row],[Etat]]),"Poniżej płacy minimalnej",""),IF(OR(tblKadry[[#This Row],[Etat]]<=0,tblKadry[[#This Row],[Etat]]>1),"Nieprawidłowy etat",""),IF(tblKadry[[#This Row],[Data_zatrudnienia]]>pDataRaportu,"Data zatrudnienia w przyszłości",""),IF(AND(tblKadry[[#This Row],[Status]]="Zwolniony",tblKadry[[#This Row],[Data_zwolnienia]]=""),"Brak daty zwolnienia",""),IF(AND(tblKadry[[#This Row],[Status]]="Aktywny",tblKadry[[#This Row],[Data_zwolnienia]]<>""),"Aktywny z datą zwolnienia",""),IF(AND(tblKadry[[#This Row],[Status]]="Aktywny",tblKadry[[#This Row],[Typ_umowy]]="Na czas określony",tblKadry[[#This Row],[Staż_lat]]>2.75),"Umowa terminowa > 33 mies. (art. 25¹ KP)",""),IF(AND(tblKadry[[#This Row],[Status]]="Aktywny",tblKadry[[#This Row],[Typ_umowy]]="Na okres próbny",tblKadry[[#This Row],[Staż_lat]]>0.25),"Okres próbny > 3 mies. (art. 25 KP)",""))
A12: P1181 | B12: Kraków | C12: Chirurgia naczyniowa | D12: Lekarz specjalista | E12: G6 | F12: M | G12: 44854 | H12: Na czas nieokreślony | I12: 1 | J12: 22020 | K12: 0 | L12: Aktywny | N12: =tblKadry[[#This Row],[Wynagrodzenie_zasadnicze]]+tblKadry[[#This Row],[Dodatek_funkcyjny]] -> 22020 | O12: =IF(OR(tblKadry[[#This Row],[Wynagrodzenie_zasadnicze]]="",tblKadry[[#This Row],[Etat]]=0),"",tblKadry[[#This Row],[Wynagrodzenie_zasadnicze]]/tblKadry[[#This Row],[Etat]]) -> 22020 | P12: =IF(AND(tblKadry[[#This Row],[Status]]="Aktywny",tblKadry[[#This Row],[Data_zatrudnienia]]<=pDataRaportu),1,0) -> 1 | Q12: =IF(tblKadry[[#This Row],[Data_zatrudnienia]]>pDataRaportu,0,ROUND(YEARFRAC(tblKadry[[#This Row],[Data_zatrudnienia]],IF(tblKadry[[#This Row],[Data_zwolnienia]]="",pDataRaportu,tblKadry[[#This Row],[Data_zwolnienia]])),1)) -> 3.9 | R12: =tblKadry[[#This Row],[Brutto_mies]]*(1+pNarzut) -> 26859.996 | S12: =_xlfn.XLOOKUP(tblKadry[[#This Row],[Grupa]],tblWidelki[Grupa],tblWidelki[Środek],"") -> 20500 | T12: =IF(tblKadry[[#This Row],[Stawka_pełny_etat]]="","",tblKadry[[#This Row],[Stawka_pełny_etat]]/tblKadry[[#This Row],[Środek_widełek]]) -> 1.0741463 | U12: =IF(tblKadry[[#This Row],[Stawka_pełny_etat]]="","",IF(tblKadry[[#This Row],[Stawka_pełny_etat]]<_xlfn.XLOOKUP(tblKadry[[#This Row],[Grupa]],tblWidelki[Grupa],tblWidelki[Min]),"Poniżej",IF(tblKadry[[#This Row],[Stawka_pełny_etat]]>_xlfn.XLOOKUP(tblKadry[[#This Row],[Grupa]],tblWidelki[Grupa],tblWidelki[Max]),"Powyżej","W widełkach"))) -> W widełkach | V12: =_xlfn.TEXTJOIN("; ",TRUE,IF(COUNTIF(tblKadry[ID_Pracownika],tblKadry[[#This Row],[ID_Pracownika]])>1,"Duplikat ID",""),IF(tblKadry[[#This Row],[Dział]]="","Brak działu",""),IF(tblKadry[[#This Row],[Wynagrodzenie_zasadnicze]]="","Brak wynagrodzenia",""),IF(AND(tblKadry[[#This Row],[Wynagrodzenie_zasadnicze]]<>"",tblKadry[[#This Row],[Brutto_mies]]<pPlacaMin*tblKadry[[#This Row],[Etat]]),"Poniżej płacy minimalnej",""),IF(OR(tblKadry[[#This Row],[Etat]]<=0,tblKadry[[#This Row],[Etat]]>1),"Nieprawidłowy etat",""),IF(tblKadry[[#This Row],[Data_zatrudnienia]]>pDataRaportu,"Data zatrudnienia w przyszłości",""),IF(AND(tblKadry[[#This Row],[Status]]="Zwolniony",tblKadry[[#This Row],[Data_zwolnienia]]=""),"Brak daty zwolnienia",""),IF(AND(tblKadry[[#This Row],[Status]]="Aktywny",tblKadry[[#This Row],[Data_zwolnienia]]<>""),"Aktywny z datą zwolnienia",""),IF(AND(tblKadry[[#This Row],[Status]]="Aktywny",tblKadry[[#This Row],[Typ_umowy]]="Na czas określony",tblKadry[[#This Row],[Staż_lat]]>2.75),"Umowa terminowa > 33 mies. (art. 25¹ KP)",""),IF(AND(tblKadry[[#This Row],[Status]]="Aktywny",tblKadry[[#This Row],[Typ_umowy]]="Na okres próbny",tblKadry[[#This Row],[Staż_lat]]>0.25),"Okres próbny > 3 mies. (art. 25 KP)",""))
A13: P1180 | B13: Bielsko-Biała | C13: Chirurgia naczyniowa | D13: Lekarz specjalista | E13: G6 | F13: M | G13: 40140 | H13: Na czas nieokreślony | I13: 1 | J13: 21850 | K13: 0 | L13: Aktywny | N13: =tblKadry[[#This Row],[Wynagrodzenie_zasadnicze]]+tblKadry[[#This Row],[Dodatek_funkcyjny]] -> 21850 | O13: =IF(OR(tblKadry[[#This Row],[Wynagrodzenie_zasadnicze]]="",tblKadry[[#This Row],[Etat]]=0),"",tblKadry[[#This Row],[Wynagrodzenie_zasadnicze]]/tblKadry[[#This Row],[Etat]]) -> 21850 | P13: =IF(AND(tblKadry[[#This Row],[Status]]="Aktywny",tblKadry[[#This Row],[Data_zatrudnienia]]<=pDataRaportu),1,0) -> 1 | Q13: =IF(tblKadry[[#This Row],[Data_zatrudnienia]]>pDataRaportu,0,ROUND(YEARFRAC(tblKadry[[#This Row],[Data_zatrudnienia]],IF(tblKadry[[#This Row],[Data_zwolnienia]]="",pDataRaportu,tblKadry[[#This Row],[Data_zwolnienia]])),1)) -> 16.9 | R13: =tblKadry[[#This Row],[Brutto_mies]]*(1+pNarzut) -> 26652.63 | S13: =_xlfn.XLOOKUP(tblKadry[[#This Row],[Grupa]],tblWidelki[Grupa],tblWidelki[Środek],"") -> 20500 | T13: =IF(tblKadry[[#This Row],[Stawka_pełny_etat]]="","",tblKadry[[#This Row],[Stawka_pełny_etat]]/tblKadry[[#This Row],[Środek_widełek]]) -> 1.0658537 | U13: =IF(tblKadry[[#This Row],[Stawka_pełny_etat]]="","",IF(tblKadry[[#This Row],[Stawka_pełny_etat]]<_xlfn.XLOOKUP(tblKadry[[#This Row],[Grupa]],tblWidelki[Grupa],tblWidelki[Min]),"Poniżej",IF(tblKadry[[#This Row],[Stawka_pełny_etat]]>_xlfn.XLOOKUP(tblKadry[[#This Row],[Grupa]],tblWidelki[Grupa],tblWidelki[Max]),"Powyżej","W widełkach"))) -> W widełkach | V13: =_xlfn.TEXTJOIN("; ",TRUE,IF(COUNTIF(tblKadry[ID_Pracownika],tblKadry[[#This Row],[ID_Pracownika]])>1,"Duplikat ID",""),IF(tblKadry[[#This Row],[Dział]]="","Brak działu",""),IF(tblKadry[[#This Row],[Wynagrodzenie_zasadnicze]]="","Brak wynagrodzenia",""),IF(AND(tblKadry[[#This Row],[Wynagrodzenie_zasadnicze]]<>"",tblKadry[[#This Row],[Brutto_mies]]<pPlacaMin*tblKadry[[#This Row],[Etat]]),"Poniżej płacy minimalnej",""),IF(OR(tblKadry[[#This Row],[Etat]]<=0,tblKadry[[#This Row],[Etat]]>1),"Nieprawidłowy etat",""),IF(tblKadry[[#This Row],[Data_zatrudnienia]]>pDataRaportu,"Data zatrudnienia w przyszłości",""),IF(AND(tblKadry[[#This Row],[Status]]="Zwolniony",tblKadry[[#This Row],[Data_zwolnienia]]=""),"Brak daty zwolnienia",""),IF(AND(tblKadry[[#This Row],[Status]]="Aktywny",tblKadry[[#This Row],[Data_zwolnienia]]<>""),"Aktywny z datą zwolnienia",""),IF(AND(tblKadry[[#This Row],[Status]]="Aktywny",tblKadry[[#This Row],[Typ_umowy]]="Na czas określony",tblKadry[[#This Row],[Staż_lat]]>2.75),"Umowa terminowa > 33 mies. (art. 25¹ KP)",""),IF(AND(tblKadry[[#This Row],[Status]]="Aktywny",tblKadry[[#This Row],[Typ_umowy]]="Na okres próbny",tblKadry[[#This Row],[Staż_lat]]>0.25),"Okres próbny > 3 mies. (art. 25 KP)",""))
A14: P1034 | B14: Bielsko-Biała | C14: Chirurgia naczyniowa | D14: Lekarz specjalista | E14: G6 | F14: K | G14: 42912 | H14: Na czas nieokreślony | I14: 1 | J14: 21640 | K14: 0 | L14: Aktywny | N14: =tblKadry[[#This Row],[Wynagrodzenie_zasadnicze]]+tblKadry[[#This Row],[Dodatek_funkcyjny]] -> 21640 | O14: =IF(OR(tblKadry[[#This Row],[Wynagrodzenie_zasadnicze]]="",tblKadry[[#This Row],[Etat]]=0),"",tblKadry[[#This Row],[Wynagrodzenie_zasadnicze]]/tblKadry[[#This Row],[Etat]]) -> 21640 | P14: =IF(AND(tblKadry[[#This Row],[Status]]="Aktywny",tblKadry[[#This Row],[Data_zatrudnienia]]<=pDataRaportu),1,0) -> 1 | Q14: =IF(tblKadry[[#This Row],[Data_zatrudnienia]]>pDataRaportu,0,ROUND(YEARFRAC(tblKadry[[#This Row],[Data_zatrudnienia]],IF(tblKadry[[#This Row],[Data_zwolnienia]]="",pDataRaportu,tblKadry[[#This Row],[Data_zwolnienia]])),1)) -> 9.3 | R14: =tblKadry[[#This Row],[Brutto_mies]]*(1+pNarzut) -> 26396.472 | S14: =_xlfn.XLOOKUP(tblKadry[[#This Row],[Grupa]],tblWidelki[Grupa],tblWidelki[Środek],"") -> 20500 | T14: =IF(tblKadry[[#This Row],[Stawka_pełny_etat]]="","",tblKadry[[#This Row],[Stawka_pełny_etat]]/tblKadry[[#This Row],[Środek_widełek]]) -> 1.0556098 | U14: =IF(tblKadry[[#This Row],[Stawka_pełny_etat]]="","",IF(tblKadry[[#This Row],[Stawka_pełny_etat]]<_xlfn.XLOOKUP(tblKadry[[#This Row],[Grupa]],tblWidelki[Grupa],tblWidelki[Min]),"Poniżej",IF(tblKadry[[#This Row],[Stawka_pełny_etat]]>_xlfn.XLOOKUP(tblKadry[[#This Row],[Grupa]],tblWidelki[Grupa],tblWidelki[Max]),"Powyżej","W widełkach"))) -> W widełkach | V14: =_xlfn.TEXTJOIN("; ",TRUE,IF(COUNTIF(tblKadry[ID_Pracownika],tblKadry[[#This Row],[ID_Pracownika]])>1,"Duplikat ID",""),IF(tblKadry[[#This Row],[Dział]]="","Brak działu",""),IF(tblKadry[[#This Row],[Wynagrodzenie_zasadnicze]]="","Brak wynagrodzenia",""),IF(AND(tblKadry[[#This Row],[Wynagrodzenie_zasadnicze]]<>"",tblKadry[[#This Row],[Brutto_mies]]<pPlacaMin*tblKadry[[#This Row],[Etat]]),"Poniżej płacy minimalnej",""),IF(OR(tblKadry[[#This Row],[Etat]]<=0,tblKadry[[#This Row],[Etat]]>1),"Nieprawidłowy etat",""),IF(tblKadry[[#This Row],[Data_zatrudnienia]]>pDataRaportu,"Data zatrudnienia w przyszłości",""),IF(AND(tblKadry[[#This Row],[Status]]="Zwolniony",tblKadry[[#This Row],[Data_zwolnienia]]=""),"Brak daty zwolnienia",""),IF(AND(tblKadry[[#This Row],[Status]]="Aktywny",tblKadry[[#This Row],[Data_zwolnienia]]<>""),"Aktywny z datą zwolnienia",""),IF(AND(tblKadry[[#This Row],[Status]]="Aktywny",tblKadry[[#This Row],[Typ_umowy]]="Na czas określony",tblKadry[[#This Row],[Staż_lat]]>2.75),"Umowa terminowa > 33 mies. (art. 25¹ KP)",""),IF(AND(tblKadry[[#This Row],[Status]]="Aktywny",tblKadry[[#This Row],[Typ_umowy]]="Na okres próbny",tblKadry[[#This Row],[Staż_lat]]>0.25),"Okres próbny > 3 mies. (art. 25 KP)",""))
A15: P1132 | B15: Ustroń | C15: Chirurgia naczyniowa | D15: Lekarz specjalista | E15: G6 | F15: M | G15: 46109 | H15: Na okres próbny | I15: 1 | J15: 21170 | K15: 0 | L15: Zwolniony | M15: 46081 | N15: =tblKadry[[#This Row],[Wynagrodzenie_zasadnicze]]+tblKadry[[#This Row],[Dodatek_funkcyjny]] -> 21170 | O15: =IF(OR(tblKadry[[#This Row],[Wynagrodzenie_zasadnicze]]="",tblKadry[[#This Row],[Etat]]=0),"",tblKadry[[#This Row],[Wynagrodzenie_zasadnicze]]/tblKadry[[#This Row],[Etat]]) -> 21170 | P15: =IF(AND(tblKadry[[#This Row],[Status]]="Aktywny",tblKadry[[#This Row],[Data_zatrudnienia]]<=pDataRaportu),1,0) -> 0 | Q15: =IF(tblKadry[[#This Row],[Data_zatrudnienia]]>pDataRaportu,0,ROUND(YEARFRAC(tblKadry[[#This Row],[Data_zatrudnienia]],IF(tblKadry[[#This Row],[Data_zwolnienia]]="",pDataRaportu,tblKadry[[#This Row],[Data_zwolnienia]])),1)) -> 0.1 | R15: =tblKadry[[#This Row],[Brutto_mies]]*(1+pNarzut) -> 25823.166 | S15: =_xlfn.XLOOKUP(tblKadry[[#This Row],[Grupa]],tblWidelki[Grupa],tblWidelki[Środek],"") -> 20500 | T15: =IF(tblKadry[[#This Row],[Stawka_pełny_etat]]="","",tblKadry[[#This Row],[Stawka_pełny_etat]]/tblKadry[[#This Row],[Środek_widełek]]) -> 1.0326829 | U15: =IF(tblKadry[[#This Row],[Stawka_pełny_etat]]="","",IF(tblKadry[[#This Row],[Stawka_pełny_etat]]<_xlfn.XLOOKUP(tblKadry[[#This Row],[Grupa]],tblWidelki[Grupa],tblWidelki[Min]),"Poniżej",IF(tblKadry[[#This Row],[Stawka_pełny_etat]]>_xlfn.XLOOKUP(tblKadry[[#This Row],[Grupa]],tblWidelki[Grupa],tblWidelki[Max]),"Powyżej","W widełkach"))) -> W widełkach | V15: =_xlfn.TEXTJOIN("; ",TRUE,IF(COUNTIF(tblKadry[ID_Pracownika],tblKadry[[#This Row],[ID_Pracownika]])>1,"Duplikat ID",""),IF(tblKadry[[#This Row],[Dział]]="","Brak działu",""),IF(tblKadry[[#This Row],[Wynagrodzenie_zasadnicze]]="","Brak wynagrodzenia",""),IF(AND(tblKadry[[#This Row],[Wynagrodzenie_zasadnicze]]<>"",tblKadry[[#This Row],[Brutto_mies]]<pPlacaMin*tblKadry[[#This Row],[Etat]]),"Poniżej płacy minimalnej",""),IF(OR(tblKadry[[#This Row],[Etat]]<=0,tblKadry[[#This Row],[Etat]]>1),"Nieprawidłowy etat",""),IF(tblKadry[[#This Row],[Data_zatrudnienia]]>pDataRaportu,"Data zatrudnienia w przyszłości",""),IF(AND(tblKadry[[#This Row],[Status]]="Zwolniony",tblKadry[[#This Row],[Data_zwolnienia]]=""),"Brak daty zwolnienia",""),IF(AND(tblKadry[[#This Row],[Status]]="Aktywny",tblKadry[[#This Row],[Data_zwolnienia]]<>""),"Aktywny z datą zwolnienia",""),IF(AND(tblKadry[[#This Row],[Status]]="Aktywny",tblKadry[[#This Row],[Typ_umowy]]="Na czas określony",tblKadry[[#This Row],[Staż_lat]]>2.75),"Umowa terminowa > 33 mies. (art. 25¹ KP)",""),IF(AND(tblKadry[[#This Row],[Status]]="Aktywny",tblKadry[[#This Row],[Typ_umowy]]="Na okres próbny",tblKadry[[#This Row],[Staż_lat]]>0.25),"Okres próbny > 3 mies. (art. 25 KP)",""))
A16: P1161 | B16: Kraków | C16: Chirurgia naczyniowa | D16: Lekarz specjalista | E16: G6 | F16: M | G16: 42492 | H16: Na czas nieokreślony | I16: 0.75 | J16: 15728 | K16: 0 | L16: Aktywny | N16: =tblKadry[[#This Row],[Wynagrodzenie_zasadnicze]]+tblKadry[[#This Row],[Dodatek_funkcyjny]] -> 15728 | O16: =IF(OR(tblKadry[[#This Row],[Wynagrodzenie_zasadnicze]]="",tblKadry[[#This Row],[Etat]]=0),"",tblKadry[[#This Row],[Wynagrodzenie_zasadnicze]]/tblKadry[[#This Row],[Etat]]) -> 20970.667 | P16: =IF(AND(tblKadry[[#This Row],[Status]]="Aktywny",tblKadry[[#This Row],[Data_zatrudnienia]]<=pDataRaportu),1,0) -> 1 | Q16: =IF(tblKadry[[#This Row],[Data_zatrudnienia]]>pDataRaportu,0,ROUND(YEARFRAC(tblKadry[[#This Row],[Data_zatrudnienia]],IF(tblKadry[[#This Row],[Data_zwolnienia]]="",pDataRaportu,tblKadry[[#This Row],[Data_zwolnienia]])),1)) -> 10.4 | R16: =tblKadry[[#This Row],[Brutto_mies]]*(1+pNarzut) -> 19185.014 | S16: =_xlfn.XLOOKUP(tblKadry[[#This Row],[Grupa]],tblWidelki[Grupa],tblWidelki[Środek],"") -> 20500 | T16: =IF(tblKadry[[#This Row],[Stawka_pełny_etat]]="","",tblKadry[[#This Row],[Stawka_pełny_etat]]/tblKadry[[#This Row],[Środek_widełek]]) -> 1.0229593 | U16: =IF(tblKadry[[#This Row],[Stawka_pełny_etat]]="","",IF(tblKadry[[#This Row],[Stawka_pełny_etat]]<_xlfn.XLOOKUP(tblKadry[[#This Row],[Grupa]],tblWidelki[Grupa],tblWidelki[Min]),"Poniżej",IF(tblKadry[[#This Row],[Stawka_pełny_etat]]>_xlfn.XLOOKUP(tblKadry[[#This Row],[Grupa]],tblWidelki[Grupa],tblWidelki[Max]),"Powyżej","W widełkach"))) -> W widełkach | V16: =_xlfn.TEXTJOIN("; ",TRUE,IF(COUNTIF(tblKadry[ID_Pracownika],tblKadry[[#This Row],[ID_Pracownika]])>1,"Duplikat ID",""),IF(tblKadry[[#This Row],[Dział]]="","Brak działu",""),IF(tblKadry[[#This Row],[Wynagrodzenie_zasadnicze]]="","Brak wynagrodzenia",""),IF(AND(tblKadry[[#This Row],[Wynagrodzenie_zasadnicze]]<>"",tblKadry[[#This Row],[Brutto_mies]]<pPlacaMin*tblKadry[[#This Row],[Etat]]),"Poniżej płacy minimalnej",""),IF(OR(tblKadry[[#This Row],[Etat]]<=0,tblKadry[[#This Row],[Etat]]>1),"Nieprawidłowy etat",""),IF(tblKadry[[#This Row],[Data_zatrudnienia]]>pDataRaportu,"Data zatrudnienia w przyszłości",""),IF(AND(tblKadry[[#This Row],[Status]]="Zwolniony",tblKadry[[#This Row],[Data_zwolnienia]]=""),"Brak daty zwolnienia",""),IF(AND(tblKadry[[#This Row],[Status]]="Aktywny",tblKadry[[#This Row],[Data_zwolnienia]]<>""),"Aktywny z datą zwolnienia",""),IF(AND(tblKadry[[#This Row],[Status]]="Aktywny",tblKadry[[#This Row],[Typ_umowy]]="Na czas określony",tblKadry[[#This Row],[Staż_lat]]>2.75),"Umowa terminowa > 33 mies. (art. 25¹ KP)",""),IF(AND(tblKadry[[#This Row],[Status]]="Aktywny",tblKadry[[#This Row],[Typ_umowy]]="Na okres próbny",tblKadry[[#This Row],[Staż_lat]]>0.25),"Okres próbny > 3 mies. (art. 25 KP)",""))
A17: P1026 | B17: Katowice | C17: Kardiologia | D17: Lekarz specjalista | E17: G6 | F17: K | G17: 40787 | H17: Na czas nieokreślony | I17: 1 | J17: 20910 | K17: 0 | L17: Aktywny | N17: =tblKadry[[#This Row],[Wynagrodzenie_zasadnicze]]+tblKadry[[#This Row],[Dodatek_funkcyjny]] -> 20910 | O17: =IF(OR(tblKadry[[#This Row],[Wynagrodzenie_zasadnicze]]="",tblKadry[[#This Row],[Etat]]=0),"",tblKadry[[#This Row],[Wynagrodzenie_zasadnicze]]/tblKadry[[#This Row],[Etat]]) -> 20910 | P17: =IF(AND(tblKadry[[#This Row],[Status]]="Aktywny",tblKadry[[#This Row],[Data_zatrudnienia]]<=pDataRaportu),1,0) -> 1 | Q17: =IF(tblKadry[[#This Row],[Data_zatrudnienia]]>pDataRaportu,0,ROUND(YEARFRAC(tblKadry[[#This Row],[Data_zatrudnienia]],IF(tblKadry[[#This Row],[Data_zwolnienia]]="",pDataRaportu,tblKadry[[#This Row],[Data_zwolnienia]])),1)) -> 15.1 | R17: =tblKadry[[#This Row],[Brutto_mies]]*(1+pNarzut) -> 25506.018 | S17: =_xlfn.XLOOKUP(tblKadry[[#This Row],[Grupa]],tblWidelki[Grupa],tblWidelki[Środek],"") -> 20500 | T17: =IF(tblKadry[[#This Row],[Stawka_pełny_etat]]="","",tblKadry[[#This Row],[Stawka_pełny_etat]]/tblKadry[[#This Row],[Środek_widełek]]) -> 1.02 | U17: =IF(tblKadry[[#This Row],[Stawka_pełny_etat]]="","",IF(tblKadry[[#This Row],[Stawka_pełny_etat]]<_xlfn.XLOOKUP(tblKadry[[#This Row],[Grupa]],tblWidelki[Grupa],tblWidelki[Min]),"Poniżej",IF(tblKadry[[#This Row],[Stawka_pełny_etat]]>_xlfn.XLOOKUP(tblKadry[[#This Row],[Grupa]],tblWidelki[Grupa],tblWidelki[Max]),"Powyżej","W widełkach"))) -> W widełkach | V17: =_xlfn.TEXTJOIN("; ",TRUE,IF(COUNTIF(tblKadry[ID_Pracownika],tblKadry[[#This Row],[ID_Pracownika]])>1,"Duplikat ID",""),IF(tblKadry[[#This Row],[Dział]]="","Brak działu",""),IF(tblKadry[[#This Row],[Wynagrodzenie_zasadnicze]]="","Brak wynagrodzenia",""),IF(AND(tblKadry[[#This Row],[Wynagrodzenie_zasadnicze]]<>"",tblKadry[[#This Row],[Brutto_mies]]<pPlacaMin*tblKadry[[#This Row],[Etat]]),"Poniżej płacy minimalnej",""),IF(OR(tblKadry[[#This Row],[Etat]]<=0,tblKadry[[#This Row],[Etat]]>1),"Nieprawidłowy etat",""),IF(tblKadry[[#This Row],[Data_zatrudnienia]]>pDataRaportu,"Data zatrudnienia w przyszłości",""),IF(AND(tblKadry[[#This Row],[Status]]="Zwolniony",tblKadry[[#This Row],[Data_zwolnienia]]=""),"Brak daty zwolnienia",""),IF(AND(tblKadry[[#This Row],[Status]]="Aktywny",tblKadry[[#This Row],[Data_zwolnienia]]<>""),"Aktywny z datą zwolnienia",""),IF(AND(tblKadry[[#This Row],[Status]]="Aktywny",tblKadry[[#This Row],[Typ_umowy]]="Na czas określony",tblKadry[[#This Row],[Staż_lat]]>2.75),"Umowa terminowa > 33 mies. (art. 25¹ KP)",""),IF(AND(tblKadry[[#This Row],[Status]]="Aktywny",tblKadry[[#This Row],[Typ_umowy]]="Na okres próbny",tblKadry[[#This Row],[Staż_lat]]>0.25),"Okres próbny > 3 mies. (art. 25 KP)",""))
A18: P1078 | B18: Bielsko-Biała | C18: Kardiologia | D18: Lekarz kierujący oddziałem | E18: G6 | F18: M | G18: 44942 | H18: Na czas nieokreślony | I18: 1 | J18: 20840 | K18: 1500 | L18: Aktywny | N18: =tblKadry[[#This Row],[Wynagrodzenie_zasadnicze]]+tblKadry[[#This Row],[Dodatek_funkcyjny]] -> 22340 | O18: =IF(OR(tblKadry[[#This Row],[Wynagrodzenie_zasadnicze]]="",tblKadry[[#This Row],[Etat]]=0),"",tblKadry[[#This Row],[Wynagrodzenie_zasadnicze]]/tblKadry[[#This Row],[Etat]]) -> 20840 | P18: =IF(AND(tblKadry[[#This Row],[Status]]="Aktywny",tblKadry[[#This Row],[Data_zatrudnienia]]<=pDataRaportu),1,0) -> 1 | Q18: =IF(tblKadry[[#This Row],[Data_zatrudnienia]]>pDataRaportu,0,ROUND(YEARFRAC(tblKadry[[#This Row],[Data_zatrudnienia]],IF(tblKadry[[#This Row],[Data_zwolnienia]]="",pDataRaportu,tblKadry[[#This Row],[Data_zwolnienia]])),1)) -> 3.7 | R18: =tblKadry[[#This Row],[Brutto_mies]]*(1+pNarzut) -> 27250.332 | S18: =_xlfn.XLOOKUP(tblKadry[[#This Row],[Grupa]],tblWidelki[Grupa],tblWidelki[Środek],"") -> 20500 | T18: =IF(tblKadry[[#This Row],[Stawka_pełny_etat]]="","",tblKadry[[#This Row],[Stawka_pełny_etat]]/tblKadry[[#This Row],[Środek_widełek]]) -> 1.0165854 | U18: =IF(tblKadry[[#This Row],[Stawka_pełny_etat]]="","",IF(tblKadry[[#This Row],[Stawka_pełny_etat]]<_xlfn.XLOOKUP(tblKadry[[#This Row],[Grupa]],tblWidelki[Grupa],tblWidelki[Min]),"Poniżej",IF(tblKadry[[#This Row],[Stawka_pełny_etat]]>_xlfn.XLOOKUP(tblKadry[[#This Row],[Grupa]],tblWidelki[Grupa],tblWidelki[Max]),"Powyżej","W widełkach"))) -> W widełkach | V18: =_xlfn.TEXTJOIN("; ",TRUE,IF(COUNTIF(tblKadry[ID_Pracownika],tblKadry[[#This Row],[ID_Pracownika]])>1,"Duplikat ID",""),IF(tblKadry[[#This Row],[Dział]]="","Brak działu",""),IF(tblKadry[[#This Row],[Wynagrodzenie_zasadnicze]]="","Brak wynagrodzenia",""),IF(AND(tblKadry[[#This Row],[Wynagrodzenie_zasadnicze]]<>"",tblKadry[[#This Row],[Brutto_mies]]<pPlacaMin*tblKadry[[#This Row],[Etat]]),"Poniżej płacy minimalnej",""),IF(OR(tblKadry[[#This Row],[Etat]]<=0,tblKadry[[#This Row],[Etat]]>1),"Nieprawidłowy etat",""),IF(tblKadry[[#This Row],[Data_zatrudnienia]]>pDataRaportu,"Data zatrudnienia w przyszłości",""),IF(AND(tblKadry[[#This Row],[Status]]="Zwolniony",tblKadry[[#This Row],[Data_zwolnienia]]=""),"Brak daty zwolnienia",""),IF(AND(tblKadry[[#This Row],[Status]]="Aktywny",tblKadry[[#This Row],[Data_zwolnienia]]<>""),"Aktywny z datą zwolnienia",""),IF(AND(tblKadry[[#This Row],[Status]]="Aktywny",tblKadry[[#This Row],[Typ_umowy]]="Na czas określony",tblKadry[[#This Row],[Staż_lat]]>2.75),"Umowa terminowa > 33 mies. (art. 25¹ KP)",""),IF(AND(tblKadry[[#This Row],[Status]]="Aktywny",tblKadry[[#This Row],[Typ_umowy]]="Na okres próbny",tblKadry[[#This Row],[Staż_lat]]>0.25),"Okres próbny > 3 mies. (art. 25 KP)",""))
